Workbook

Sheet Read me
B2: DCCREG turbine, air build: cost sheet template
B4: What it does
B5: Every stack of the vane matrix (2700 designs: gap, vane thickness, outer radius, vane count, sector width) is costed with live formulas on the Inputs sheet.
B6: The Optimum sheet picks the design that meets your targets at the lowest total cost (or cost per watt), and lists the next ten.
B7: Targets: the voltage the electric field on the core needs, the electrostatic pump's power and gain, the vane and radius caps, corona-safe rims, and the AH's steady ampere-turns.
B9: How to use it
B10: 1. On Inputs, edit the yellow cells with blue text: the targets first, then the materials and the process prices.
B11: 2. On BOM fixed, edit the quantities and unit prices of the parts that do not depend on the stack (blue text).
B12: 3. Read the result on Optimum. Nothing else needs editing: black cells are formulas, green cells link to another sheet.
B13: The Designs sheet's physics columns (grey header note) are results of sim/vane_matrix.py; do not edit them.
B15: Legend
B16: Blue text on yellow: an input to fill in (key assumption). Blue text: an input. Black: a formula. Green: a link to another sheet.
... B23: Geometry-derived quantities (cut and rounded-edge lengths, G10 masses): see the Notes sheet.

Sheet Optimum
B2: Optimum: the design that meets the targets at the lowest cost
B3: Formulas only. Change the targets and prices on Inputs.
B5: Designs that meet the targets | C5: =COUNTIF(MEETS,1) -> 177 | E5: AH steady cusp (does not depend on the stack)
B6: Best row on Designs | C6: =IF(MIN(SCORE)>=1000000000000,0,MATCH(MIN(SCORE),SCORE,0)) -> 1279 | E6: ="delivered "&TEXT(AT_DELIVERED,"0")&" A-turns per coil against "&TEXT(AT_TARGET,"0")&" wanted" -> delivered 300 A-turns per coil against 300 wanted
B7: Status | C7: =IF(C6=0,"No design meets the targets: relax them on Inputs","Best design below") -> Best design below | E7: =IF(AT_DELIVERED>=AT_TARGET,"met with the 22 mF bypass","re-size the AH or the pump (not costed here)") -> met with the 22 mF bypass
B9: best design | C9: value | D9: unit
B10: gap | C10: =IF(BEST=0,"",INDEX(Designs!$B$5:$B$2704,BEST)) -> 5 | D10: mm
B11: vane thickness (full round) | C11: =IF(BEST=0,"",INDEX(Designs!$C$5:$C$2704,BEST)) -> 2 | D11: mm
B12: outer radius | C12: =IF(BEST=0,"",INDEX(Designs!$D$5:$D$2704,BEST)) -> 200 | D12: mm
B13: sector width | C13: =IF(BEST=0,"",INDEX(Designs!$E$5:$E$2704,BEST)) -> 18 | D13: deg
B14: vanes per varicap per side | C14: =IF(BEST=0,"",INDEX(Designs!$F$5:$F$2704,BEST)) -> 4 | D14: stator = rotor
B15: operating peak | C15: =IF(BEST=0,"",INDEX(Designs!$G$5:$G$2704,BEST)) -> 11.211605 | D15: kV
B16: C_max | C16: =IF(BEST=0,"",INDEX(Designs!$I$5:$I$2704,BEST)) -> 470.89352 | D16: pF
B17: kappa | C17: =IF(BEST=0,"",INDEX(Designs!$J$5:$J$2704,BEST)) -> 16.69178
B18: z | C18: =IF(BEST=0,"",INDEX(Designs!$K$5:$K$2704,BEST)) -> 1.456209
B19: clamped power | C19: =IF(BEST=0,"",INDEX(Designs!$L$5:$L$2704,BEST)) -> 2.34646 | D19: W
B20: stacks per side | C20: =IF(BEST=0,"",INDEX(Designs!$M$5:$M$2704,BEST)) -> 79 | D20: mm
B21: tube length | C21: =IF(BEST=0,"",INDEX(Designs!$N$5:$N$2704,BEST)) -> 758 | D21: mm
B22: rim onset, handled | C22: =IF(BEST=0,"",INDEX(Designs!$O$5:$O$2704,BEST)) -> 11.4365 | D22: kV
B23: vane metal | C23: =IF(BEST=0,"",INDEX(Designs!$X$5:$X$2704,BEST)) -> 47.962222 | D23: =CUR -> EUR
B24: plate metal | C24: =IF(BEST=0,"",INDEX(Designs!$Y$5:$Y$2704,BEST)) -> 60.919879 | D24: =CUR -> EUR
B25: cutting | C25: =IF(BEST=0,"",INDEX(Designs!$Z$5:$Z$2704,BEST)) -> 122.4292 | D25: =CUR -> EUR
B26: full rounds | C26: =IF(BEST=0,"",INDEX(Designs!$AA$5:$AA$2704,BEST)) -> 269.6637 | D26: =CUR -> EUR
B27: deburr + polish | C27: =IF(BEST=0,"",INDEX(Designs!$AB$5:$AB$2704,BEST)) -> 192 | D27: =CUR -> EUR
B28: spacers + assembly | C28: =IF(BEST=0,"",INDEX(Designs!$AC$5:$AC$2704,BEST)) -> 318 | D28: =CUR -> EUR
B29: G10 cage + sleeve | C29: =IF(BEST=0,"",INDEX(Designs!$AD$5:$AD$2704,BEST)) -> 177.77856 | D29: =CUR -> EUR
B30: shaft | C30: =IF(BEST=0,"",INDEX(Designs!$AE$5:$AE$2704,BEST)) -> 170.96 | D30: =CUR -> EUR
B31: HV parts | C31: =IF(BEST=0,"",INDEX(Designs!$AF$5:$AF$2704,BEST)) -> 80.9 | D31: =CUR -> EUR
B32: stack subtotal | C32: =IF(BEST=0,"",INDEX(Designs!$AG$5:$AG$2704,BEST)) -> 1440.6136 | D32: =CUR -> EUR
B33: fixed BOM | C33: =IF(BEST=0,"",INDEX(Designs!$AH$5:$AH$2704,BEST)) -> 3461 | D33: =CUR -> EUR
B34: total incl. contingency | C34: =IF(BEST=0,"",INDEX(Designs!$AI$5:$AI$2704,BEST)) -> 5636.8556 | D34: =CUR -> EUR
B35: per watt | C35: =IF(BEST=0,"",INDEX(Designs!$AJ$5:$AJ$2704,BEST)) -> 2402.2807 | D35: =CUR -> EUR
B38: The next best (rank by the objective on Inputs)
B39: rank | C39: gap (mm) | D39: t (mm) | E39: r_out (mm) | F39: sector | G39: N | H39: V_op (kV) | I39: z | J39: P (W) | K39: stack/side (mm) | L39: ="stack subtotal ("&CUR&")" -> stack subtotal (EUR) | M39: ="total ("&CUR&")" -> total (EUR) | N39: ="per watt ("&CUR&")" -> per watt (EUR)
B40: 1 | C40: =IF(IF(SMALL(SCORE,1)>=1000000000000,0,MATCH(SMALL(SCORE,1),SCORE,0))=0,"",INDEX(Designs!$B$5:$B$2704,IF(SMALL(SCORE,1)>=1000000000000,0,MATCH(SMALL(SCORE,1),SCORE,0)))) -> 5 | D40: =IF(IF(SMALL(SCORE,1)>=1000000000000,0,MATCH(SMALL(SCORE,1),SCORE,0))=0,"",INDEX(Designs!$C$5:$C$2704,IF(SMALL(SCORE,1)>=1000000000000,0,MATCH(SMALL(SCORE,1),SCORE,0)))) -> 2 | E40: =IF(IF(SMALL(SCORE,1)>=1000000000000,0,MATCH(SMALL(SCORE,1),SCORE,0))=0,"",INDEX(Designs!$D$5:$D$2704,IF(SMALL(SCORE,1)>=1000000000000,0,MATCH(SMALL(SCORE,1),SCORE,0)))) -> 200 | F40: =IF(IF(SMALL(SCORE,1)>=1000000000000,0,MATCH(SMALL(SCORE,1),SCORE,0))=0,"",INDEX(Designs!$E$5:$E$2704,IF(SMALL(SCORE,1)>=1000000000000,0,MATCH(SMALL(SCORE,1),SCORE,0)))) -> 18 | G40: =IF(IF(SMALL(SCORE,1)>=1000000000000,0,MATCH(SMALL(SCORE,1),SCORE,0))=0,"",INDEX(Designs!$F$5:$F$2704,IF(SMALL(SCORE,1)>=1000000000000,0,MATCH(SMALL(SCORE,1),SCORE,0)))) -> 4 | H40: =IF(IF(SMALL(SCORE,1)>=1000000000000,0,MATCH(SMALL(SCORE,1),SCORE,0))=0,"",INDEX(Designs!$G$5:$G$2704,IF(SMALL(SCORE,1)>=1000000000000,0,MATCH(SMALL(SCORE,1),SCORE,0)))) -> 11.211605 | I40: =IF(IF(SMALL(SCORE,1)>=1000000000000,0,MATCH(SMALL(SCORE,1),SCORE,0))=0,"",INDEX(Designs!$K$5:$K$2704,IF(SMALL(SCORE,1)>=1000000000000,0,MATCH(SMALL(SCORE,1),SCORE,0)))) -> 1.456209 | J40: =IF(IF(SMALL(SCORE,1)>=1000000000000,0,MATCH(SMALL(SCORE,1),SCORE,0))=0,"",INDEX(Designs!$L$5:$L$2704,IF(SMALL(SCORE,1)>=1000000000000,0,MATCH(SMALL(SCORE,1),SCORE,0)))) -> 2.34646 | K40: =IF(IF(SMALL(SCORE,1)>=1000000000000,0,MATCH(SMALL(SCORE,1),SCORE,0))=0,"",INDEX(Designs!$M$5:$M$2704,IF(SMALL(SCORE,1)>=1000000000000,0,MATCH(SMALL(SCORE,1),SCORE,0)))) -> 79 | L40: =IF(IF(SMALL(SCORE,1)>=1000000000000,0,MATCH(SMALL(SCORE,1),SCORE,0))=0,"",INDEX(Designs!$AG$5:$AG$2704,IF(SMALL(SCORE,1)>=1000000000000,0,MATCH(SMALL(SCORE,1),SCORE,0)))) -> 1440.6136 | M40: =IF(IF(SMALL(SCORE,1)>=1000000000000,0,MATCH(SMALL(SCORE,1),SCORE,0))=0,"",INDEX(Designs!$AI$5:$AI$2704,IF(SMALL(SCORE,1)>=1000000000000,0,MATCH(SMALL(SCORE,1),SCORE,0)))) -> 5636.8556 | N40: =IF(IF(SMALL(SCORE,1)>=1000000000000,0,MATCH(SMALL(SCORE,1),SCORE,0))=0,"",INDEX(Designs!$AJ$5:$AJ$2704,IF(SMALL(SCORE,1)>=1000000000000,0,MATCH(SMALL(SCORE,1),SCORE,0)))) -> 2402.2807
B41: 2 | C41: =IF(IF(SMALL(SCORE,2)>=1000000000000,0,MATCH(SMALL(SCORE,2),SCORE,0))=0,"",INDEX(Designs!$B$5:$B$2704,IF(SMALL(SCORE,2)>=1000000000000,0,MATCH(SMALL(SCORE,2),SCORE,0)))) -> 5 | D41: =IF(IF(SMALL(SCORE,2)>=1000000000000,0,MATCH(SMALL(SCORE,2),SCORE,0))=0,"",INDEX(Designs!$C$5:$C$2704,IF(SMALL(SCORE,2)>=1000000000000,0,MATCH(SMALL(SCORE,2),SCORE,0)))) -> 2 | E41: =IF(IF(SMALL(SCORE,2)>=1000000000000,0,MATCH(SMALL(SCORE,2),SCORE,0))=0,"",INDEX(Designs!$D$5:$D$2704,IF(SMALL(SCORE,2)>=1000000000000,0,MATCH(SMALL(SCORE,2),SCORE,0)))) -> 175 | F41: =IF(IF(SMALL(SCORE,2)>=1000000000000,0,MATCH(SMALL(SCORE,2),SCORE,0))=0,"",INDEX(Designs!$E$5:$E$2704,IF(SMALL(SCORE,2)>=1000000000000,0,MATCH(SMALL(SCORE,2),SCORE,0)))) -> 26 | G41: =IF(IF(SMALL(SCORE,2)>=1000000000000,0,MATCH(SMALL(SCORE,2),SCORE,0))=0,"",INDEX(Designs!$F$5:$F$2704,IF(SMALL(SCORE,2)>=1000000000000,0,MATCH(SMALL(SCORE,2),SCORE,0)))) -> 4 | H41: =IF(IF(SMALL(SCORE,2)>=1000000000000,0,MATCH(SMALL(SCORE,2),SCORE,0))=0,"",INDEX(Designs!$G$5:$G$2704,IF(SMALL(SCORE,2)>=1000000000000,0,MATCH(SMALL(SCORE,2),SCORE,0)))) -> 11.211605 | I41: =IF(IF(SMALL(SCORE,2)>=1000000000000,0,MATCH(SMALL(SCORE,2),SCORE,0))=0,"",INDEX(Designs!$K$5:$K$2704,IF(SMALL(SCORE,2)>=1000000000000,0,MATCH(SMALL(SCORE,2),SCORE,0)))) -> 1.376377 | J41: =IF(IF(SMALL(SCORE,2)>=1000000000000,0,MATCH(SMALL(SCORE,2),SCORE,0))=0,"",INDEX(Designs!$L$5:$L$2704,IF(SMALL(SCORE,2)>=1000000000000,0,MATCH(SMALL(SCORE,2),SCORE,0)))) -> 2.19411 | K41: =IF(IF(SMALL(SCORE,2)>=1000000000000,0,MATCH(SMALL(SCORE,2),SCORE,0))=0,"",INDEX(Designs!$M$5:$M$2704,IF(SMALL(SCORE,2)>=1000000000000,0,MATCH(SMALL(SCORE,2),SCORE,0)))) -> 86 | L41: =IF(IF(SMALL(SCORE,2)>=1000000000000,0,MATCH(SMALL(SCORE,2),SCORE,0))=0,"",INDEX(Designs!$AG$5:$AG$2704,IF(SMALL(SCORE,2)>=1000000000000,0,MATCH(SMALL(SCORE,2),SCORE,0)))) -> 1440.6911 | M41: =IF(IF(SMALL(SCORE,2)>=1000000000000,0,MATCH(SMALL(SCORE,2),SCORE,0))=0,"",INDEX(Designs!$AI$5:$AI$2704,IF(SMALL(SCORE,2)>=1000000000000,0,MATCH(SMALL(SCORE,2),SCORE,0)))) -> 5636.9448 | N41: =IF(IF(SMALL(SCORE,2)>=1000000000000,0,MATCH(SMALL(SCORE,2),SCORE,0))=0,"",INDEX(Designs!$AJ$5:$AJ$2704,IF(SMALL(SCORE,2)>=1000000000000,0,MATCH(SMALL(SCORE,2),SCORE,0)))) -> 2569.1259
B42: 3 | C42: =IF(IF(SMALL(SCORE,3)>=1000000000000,0,MATCH(SMALL(SCORE,3),SCORE,0))=0,"",INDEX(Designs!$B$5:$B$2704,IF(SMALL(SCORE,3)>=1000000000000,0,MATCH(SMALL(SCORE,3),SCORE,0)))) -> 5 | D42: =IF(IF(SMALL(SCORE,3)>=1000000000000,0,MATCH(SMALL(SCORE,3),SCORE,0))=0,"",INDEX(Designs!$C$5:$C$2704,IF(SMALL(SCORE,3)>=1000000000000,0,MATCH(SMALL(SCORE,3),SCORE,0)))) -> 2 | E42: =IF(IF(SMALL(SCORE,3)>=1000000000000,0,MATCH(SMALL(SCORE,3),SCORE,0))=0,"",INDEX(Designs!$D$5:$D$2704,IF(SMALL(SCORE,3)>=1000000000000,0,MATCH(SMALL(SCORE,3),SCORE,0)))) -> 200 | F42: =IF(IF(SMALL(SCORE,3)>=1000000000000,0,MATCH(SMALL(SCORE,3),SCORE,0))=0,"",INDEX(Designs!$E$5:$E$2704,IF(SMALL(SCORE,3)>=1000000000000,0,MATCH(SMALL(SCORE,3),SCORE,0)))) -> 22 | G42: =IF(IF(SMALL(SCORE,3)>=1000000000000,0,MATCH(SMALL(SCORE,3),SCORE,0))=0,"",INDEX(Designs!$F$5:$F$2704,IF(SMALL(SCORE,3)>=1000000000000,0,MATCH(SMALL(SCORE,3),SCORE,0)))) -> 4 | H42: =IF(IF(SMALL(SCORE,3)>=1000000000000,0,MATCH(SMALL(SCORE,3),SCORE,0))=0,"",INDEX(Designs!$G$5:$G$2704,IF(SMALL(SCORE,3)>=1000000000000,0,MATCH(SMALL(SCORE,3),SCORE,0)))) -> 11.211605 | I42: =IF(IF(SMALL(SCORE,3)>=1000000000000,0,MATCH(SMALL(SCORE,3),SCORE,0))=0,"",INDEX(Designs!$K$5:$K$2704,IF(SMALL(SCORE,3)>=1000000000000,0,MATCH(SMALL(SCORE,3),SCORE,0)))) -> 1.460535 | J42: =IF(IF(SMALL(SCORE,3)>=1000000000000,0,MATCH(SMALL(SCORE,3),SCORE,0))=0,"",INDEX(Designs!$L$5:$L$2704,IF(SMALL(SCORE,3)>=1000000000000,0,MATCH(SMALL(SCORE,3),SCORE,0)))) -> 2.850318 | K42: =IF(IF(SMALL(SCORE,3)>=1000000000000,0,MATCH(SMALL(SCORE,3),SCORE,0))=0,"",INDEX(Designs!$M$5:$M$2704,IF(SMALL(SCORE,3)>=1000000000000,0,MATCH(SMALL(SCORE,3),SCORE,0)))) -> 79 | L42: =IF(IF(SMALL(SCORE,3)>=1000000000000,0,MATCH(SMALL(SCORE,3),SCORE,0))=0,"",INDEX(Designs!$AG$5:$AG$2704,IF(SMALL(SCORE,3)>=1000000000000,0,MATCH(SMALL(SCORE,3),SCORE,0)))) -> 1448.7362 | M42: =IF(IF(SMALL(SCORE,3)>=1000000000000,0,MATCH(SMALL(SCORE,3),SCORE,0))=0,"",INDEX(Designs!$AI$5:$AI$2704,IF(SMALL(SCORE,3)>=1000000000000,0,MATCH(SMALL(SCORE,3),SCORE,0)))) -> 5646.1966 | N42: =IF(IF(SMALL(SCORE,3)>=1000000000000,0,MATCH(SMALL(SCORE,3),SCORE,0))=0,"",INDEX(Designs!$AJ$5:$AJ$2704,IF(SMALL(SCORE,3)>=1000000000000,0,MATCH(SMALL(SCORE,3),SCORE,0)))) -> 1980.9006
B43: 4 | C43: =IF(IF(SMALL(SCORE,4)>=1000000000000,0,MATCH(SMALL(SCORE,4),SCORE,0))=0,"",INDEX(Designs!$B$5:$B$2704,IF(SMALL(SCORE,4)>=1000000000000,0,MATCH(SMALL(SCORE,4),SCORE,0)))) -> 5 | D43: =IF(IF(SMALL(SCORE,4)>=1000000000000,0,MATCH(SMALL(SCORE,4),SCORE,0))=0,"",INDEX(Designs!$C$5:$C$2704,IF(SMALL(SCORE,4)>=1000000000000,0,MATCH(SMALL(SCORE,4),SCORE,0)))) -> 2.5 | E43: =IF(IF(SMALL(SCORE,4)>=1000000000000,0,MATCH(SMALL(SCORE,4),SCORE,0))=0,"",INDEX(Designs!$D$5:$D$2704,IF(SMALL(SCORE,4)>=1000000000000,0,MATCH(SMALL(SCORE,4),SCORE,0)))) -> 175 | F43: =IF(IF(SMALL(SCORE,4)>=1000000000000,0,MATCH(SMALL(SCORE,4),SCORE,0))=0,"",INDEX(Designs!$E$5:$E$2704,IF(SMALL(SCORE,4)>=1000000000000,0,MATCH(SMALL(SCORE,4),SCORE,0)))) -> 26 | G43: =IF(IF(SMALL(SCORE,4)>=1000000000000,0,MATCH(SMALL(SCORE,4),SCORE,0))=0,"",INDEX(Designs!$F$5:$F$2704,IF(SMALL(SCORE,4)>=1000000000000,0,MATCH(SMALL(SCORE,4),SCORE,0)))) -> 4 | H43: =IF(IF(SMALL(SCORE,4)>=1000000000000,0,MATCH(SMALL(SCORE,4),SCORE,0))=0,"",INDEX(Designs!$G$5:$G$2704,IF(SMALL(SCORE,4)>=1000000000000,0,MATCH(SMALL(SCORE,4),SCORE,0)))) -> 11.211605 | I43: =IF(IF(SMALL(SCORE,4)>=1000000000000,0,MATCH(SMALL(SCORE,4),SCORE,0))=0,"",INDEX(Designs!$K$5:$K$2704,IF(SMALL(SCORE,4)>=1000000000000,0,MATCH(SMALL(SCORE,4),SCORE,0)))) -> 1.365839 | J43: =IF(IF(SMALL(SCORE,4)>=1000000000000,0,MATCH(SMALL(SCORE,4),SCORE,0))=0,"",INDEX(Designs!$L$5:$L$2704,IF(SMALL(SCORE,4)>=1000000000000,0,MATCH(SMALL(SCORE,4),SCORE,0)))) -> 2.15359 | K43: =IF(IF(SMALL(SCORE,4)>=1000000000000,0,MATCH(SMALL(SCORE,4),SCORE,0))=0,"",INDEX(Designs!$M$5:$M$2704,IF(SMALL(SCORE,4)>=1000000000000,0,MATCH(SMALL(SCORE,4),SCORE,0)))) -> 92.5 | L43: =IF(IF(SMALL(SCORE,4)>=1000000000000,0,MATCH(SMALL(SCORE,4),SCORE,0))=0,"",INDEX(Designs!$AG$5:$AG$2704,IF(SMALL(SCORE,4)>=1000000000000,0,MATCH(SMALL(SCORE,4),SCORE,0)))) -> 1477.0888 | M43: =IF(IF(SMALL(SCORE,4)>=1000000000000,0,MATCH(SMALL(SCORE,4),SCORE,0))=0,"",INDEX(Designs!$AI$5:$AI$2704,IF(SMALL(SCORE,4)>=1000000000000,0,MATCH(SMALL(SCORE,4),SCORE,0)))) -> 5678.8022 | N43: =IF(IF(SMALL(SCORE,4)>=1000000000000,0,MATCH(SMALL(SCORE,4),SCORE,0))=0,"",INDEX(Designs!$AJ$5:$AJ$2704,IF(SMALL(SCORE,4)>=1000000000000,0,MATCH(SMALL(SCORE,4),SCORE,0)))) -> 2636.9003
B44: 5 | C44: =IF(IF(SMALL(SCORE,5)>=1000000000000,0,MATCH(SMALL(SCORE,5),SCORE,0))=0,"",INDEX(Designs!$B$5:$B$2704,IF(SMALL(SCORE,5)>=1000000000000,0,MATCH(SMALL(SCORE,5),SCORE,0)))) -> 5 | D44: =IF(IF(SMALL(SCORE,5)>=1000000000000,0,MATCH(SMALL(SCORE,5),SCORE,0))=0,"",INDEX(Designs!$C$5:$C$2704,IF(SMALL(SCORE,5)>=1000000000000,0,MATCH(SMALL(SCORE,5),SCORE,0)))) -> 2.5 | E44: =IF(IF(SMALL(SCORE,5)>=1000000000000,0,MATCH(SMALL(SCORE,5),SCORE,0))=0,"",INDEX(Designs!$D$5:$D$2704,IF(SMALL(SCORE,5)>=1000000000000,0,MATCH(SMALL(SCORE,5),SCORE,0)))) -> 200 | F44: =IF(IF(SMALL(SCORE,5)>=1000000000000,0,MATCH(SMALL(SCORE,5),SCORE,0))=0,"",INDEX(Designs!$E$5:$E$2704,IF(SMALL(SCORE,5)>=1000000000000,0,MATCH(SMALL(SCORE,5),SCORE,0)))) -> 18 | G44: =IF(IF(SMALL(SCORE,5)>=1000000000000,0,MATCH(SMALL(SCORE,5),SCORE,0))=0,"",INDEX(Designs!$F$5:$F$2704,IF(SMALL(SCORE,5)>=1000000000000,0,MATCH(SMALL(SCORE,5),SCORE,0)))) -> 4 | H44: =IF(IF(SMALL(SCORE,5)>=1000000000000,0,MATCH(SMALL(SCORE,5),SCORE,0))=0,"",INDEX(Designs!$G$5:$G$2704,IF(SMALL(SCORE,5)>=1000000000000,0,MATCH(SMALL(SCORE,5),SCORE,0)))) -> 11.211605 | I44: =IF(IF(SMALL(SCORE,5)>=1000000000000,0,MATCH(SMALL(SCORE,5),SCORE,0))=0,"",INDEX(Designs!$K$5:$K$2704,IF(SMALL(SCORE,5)>=1000000000000,0,MATCH(SMALL(SCORE,5),SCORE,0)))) -> 1.44822 | J44: =IF(IF(SMALL(SCORE,5)>=1000000000000,0,MATCH(SMALL(SCORE,5),SCORE,0))=0,"",INDEX(Designs!$L$5:$L$2704,IF(SMALL(SCORE,5)>=1000000000000,0,MATCH(SMALL(SCORE,5),SCORE,0)))) -> 2.324734 | K44: =IF(IF(SMALL(SCORE,5)>=1000000000000,0,MATCH(SMALL(SCORE,5),SCORE,0))=0,"",INDEX(Designs!$M$5:$M$2704,IF(SMALL(SCORE,5)>=1000000000000,0,MATCH(SMALL(SCORE,5),SCORE,0)))) -> 85 | L44: =IF(IF(SMALL(SCORE,5)>=1000000000000,0,MATCH(SMALL(SCORE,5),SCORE,0))=0,"",INDEX(Designs!$AG$5:$AG$2704,IF(SMALL(SCORE,5)>=1000000000000,0,MATCH(SMALL(SCORE,5),SCORE,0)))) -> 1477.5429 | M44: =IF(IF(SMALL(SCORE,5)>=1000000000000,0,MATCH(SMALL(SCORE,5),SCORE,0))=0,"",INDEX(Designs!$AI$5:$AI$2704,IF(SMALL(SCORE,5)>=1000000000000,0,MATCH(SMALL(SCORE,5),SCORE,0)))) -> 5679.3244 | N44: =IF(IF(SMALL(SCORE,5)>=1000000000000,0,MATCH(SMALL(SCORE,5),SCORE,0))=0,"",INDEX(Designs!$AJ$5:$AJ$2704,IF(SMALL(SCORE,5)>=1000000000000,0,MATCH(SMALL(SCORE,5),SCORE,0)))) -> 2442.9997
B45: 6 | C45: =IF(IF(SMALL(SCORE,6)>=1000000000000,0,MATCH(SMALL(SCORE,6),SCORE,0))=0,"",INDEX(Designs!$B$5:$B$2704,IF(SMALL(SCORE,6)>=1000000000000,0,MATCH(SMALL(SCORE,6),SCORE,0)))) -> 6 | D45: =IF(IF(SMALL(SCORE,6)>=1000000000000,0,MATCH(SMALL(SCORE,6),SCORE,0))=0,"",INDEX(Designs!$C$5:$C$2704,IF(SMALL(SCORE,6)>=1000000000000,0,MATCH(SMALL(SCORE,6),SCORE,0)))) -> 2.5 | E45: =IF(IF(SMALL(SCORE,6)>=1000000000000,0,MATCH(SMALL(SCORE,6),SCORE,0))=0,"",INDEX(Designs!$D$5:$D$2704,IF(SMALL(SCORE,6)>=1000000000000,0,MATCH(SMALL(SCORE,6),SCORE,0)))) -> 175 | F45: =IF(IF(SMALL(SCORE,6)>=1000000000000,0,MATCH(SMALL(SCORE,6),SCORE,0))=0,"",INDEX(Designs!$E$5:$E$2704,IF(SMALL(SCORE,6)>=1000000000000,0,MATCH(SMALL(SCORE,6),SCORE,0)))) -> 22 | G45: =IF(IF(SMALL(SCORE,6)>=1000000000000,0,MATCH(SMALL(SCORE,6),SCORE,0))=0,"",INDEX(Designs!$F$5:$F$2704,IF(SMALL(SCORE,6)>=1000000000000,0,MATCH(SMALL(SCORE,6),SCORE,0)))) -> 4 | H45: =IF(IF(SMALL(SCORE,6)>=1000000000000,0,MATCH(SMALL(SCORE,6),SCORE,0))=0,"",INDEX(Designs!$G$5:$G$2704,IF(SMALL(SCORE,6)>=1000000000000,0,MATCH(SMALL(SCORE,6),SCORE,0)))) -> 13.132078 | I45: =IF(IF(SMALL(SCORE,6)>=1000000000000,0,MATCH(SMALL(SCORE,6),SCORE,0))=0,"",INDEX(Designs!$K$5:$K$2704,IF(SMALL(SCORE,6)>=1000000000000,0,MATCH(SMALL(SCORE,6),SCORE,0)))) -> 1.337841 | J45: =IF(IF(SMALL(SCORE,6)>=1000000000000,0,MATCH(SMALL(SCORE,6),SCORE,0))=0,"",INDEX(Designs!$L$5:$L$2704,IF(SMALL(SCORE,6)>=1000000000000,0,MATCH(SMALL(SCORE,6),SCORE,0)))) -> 2.009521 | K45: =IF(IF(SMALL(SCORE,6)>=1000000000000,0,MATCH(SMALL(SCORE,6),SCORE,0))=0,"",INDEX(Designs!$M$5:$M$2704,IF(SMALL(SCORE,6)>=1000000000000,0,MATCH(SMALL(SCORE,6),SCORE,0)))) -> 104.5 | L45: =IF(IF(SMALL(SCORE,6)>=1000000000000,0,MATCH(SMALL(SCORE,6),SCORE,0))=0,"",INDEX(Designs!$AG$5:$AG$2704,IF(SMALL(SCORE,6)>=1000000000000,0,MATCH(SMALL(SCORE,6),SCORE,0)))) -> 1498.4975 | M45: =IF(IF(SMALL(SCORE,6)>=1000000000000,0,MATCH(SMALL(SCORE,6),SCORE,0))=0,"",INDEX(Designs!$AI$5:$AI$2704,IF(SMALL(SCORE,6)>=1000000000000,0,MATCH(SMALL(SCORE,6),SCORE,0)))) -> 5703.4222 | N45: =IF(IF(SMALL(SCORE,6)>=1000000000000,0,MATCH(SMALL(SCORE,6),SCORE,0))=0,"",INDEX(Designs!$AJ$5:$AJ$2704,IF(SMALL(SCORE,6)>=1000000000000,0,MATCH(SMALL(SCORE,6),SCORE,0)))) -> 2838.1998
...

Sheet Inputs
B2: Inputs: targets, materials and prices
B3: Edit the yellow cells (blue text). Black cells are formulas.
B5: item | C5: value | D5: unit | E5: source / note
B6: Currency label | C6: EUR | E6: Used in the headers. Every price below is a placeholder in this currency.
B7: Targets
B8: Electric field wanted on the core | C8: 2 | D8: kV/cm | E8: Placeholder: set your target. With the spacing below it sets the voltage the electrostatic pump must hold on the core.
B9: Core electrode spacing | C9: 50 | D9: mm | E9: Placeholder: the distance across which that field is applied (e.g. between the two cones at the centre).
B10: Voltage needed on the core | C10: =E_CORE*D_CORE/10 -> 10 | D10: kV | E10: Formula: E x spacing. A design qualifies when its operating peak (air breakdown / 1.5) is at least this.
B11: Minimum electrostatic pump power (clamped) | C11: 2 | D11: W | E11: Placeholder: what the core's leakage, corona and margin need. The pump only has to replace the charge that leaks away.
B12: Minimum gain per cycle z | C12: 1.3 | E12: The searches' floor; real losses eat into a thin margin.
B13: Maximum vanes per varicap per side | C13: 6 | E13: The cap (6 stator + 6 rotor). Set 16 to lift it.
B14: Maximum vane outer radius | C14: 300 | D14: mm | E14: 150 today; the matrix runs to 300.
B15: Require corona-safe rims (1 yes, 0 no) | C15: 1 | E15: Rims must hold the operating peak on a handled surface (Peek, m 0.85).
B16: AH steady ampere-turns wanted at the centre | C16: 300 | D16: A-turns | E16: The stable cusp's strength per coil. Checked on the Optimum sheet; it does not depend on the stack.
B17: AH steady ampere-turns delivered | C17: 300 | D17: A-turns | E17: 22 mF across each AH coil at the pick (sim/ah_steady_cusp_results.json). Above this, the AH or the pump must be re-sized (not costed here).
B18: Objective (1 lowest total cost, 2 lowest cost per watt) | C18: 1 | E18: How the Optimum sheet ranks the designs that meet the targets.
B20: Materials
B21: material | C21: density (kg/m³) | D21: ="price ("&CUR&"/kg)" -> price (EUR/kg) | E21: source / note
B22: Al 5083 plate | C22: 2660 | D22: 9 | E22: Marine-grade plate; machines and polishes well. Placeholder price.
B23: Al 6082-T6 plate | C23: 2700 | D23: 10 | E23: Structural plate; the default the sweep's masses assume (2700). Placeholder.
B24: Al 1050 sheet | C24: 2705 | D24: 8 | E24: Soft, cheap; harder to give a polished full round. Placeholder.
B25: Stainless 304 plate | C25: 7930 | D25: 7 | E25: Holds a polish; 3x the mass. Placeholder.
B26: Copper C101 plate | C26: 8940 | D26: 14 | E26: Best finish and conductivity; 3.3x the mass. Placeholder.
B28: Vane material (rotor and stator vanes) | C28: Al 5083 plate | E28: Pick from the list above.
B29: Ca / Cb plate material | C29: Al 5083 plate | E29: Pick from the list above. They need not match the vanes.
B30: Vane density | C30: =INDEX(MAT_RHO,MATCH(VANE_MAT,MAT_NAMES,0)) -> 2660 | D30: kg/m³ | E30: Formula.
B31: Vane price | C31: =INDEX(MAT_PRICE,MATCH(VANE_MAT,MAT_NAMES,0)) -> 9 | D31: /kg | E31: Formula.
B32: Plate density | C32: =INDEX(MAT_RHO,MATCH(PLATE_MAT,MAT_NAMES,0)) -> 2660 | D32: kg/m³ | E32: Formula.
B33: Plate price | C33: =INDEX(MAT_PRICE,MATCH(PLATE_MAT,MAT_NAMES,0)) -> 9 | D33: /kg | E33: Formula.
B34: Plate yield loss (extra stock for nesting sectors) | C34: 0.35 | D34: fraction | E34: Placeholder: sectored discs waste a lot of a rectangular plate.
B36: Process prices (placeholders [RH]: replace with quotes)
B37: Waterjet / laser cutting | C37: 1.5 | D37: /m of cut | E37: Placeholder, 1.5-4 mm Al.
B38: Cutting set-up per part | C38: 1 | D38: /part | E38: Placeholder: pierce, handling.
B39: CNC full-round edge | C39: 5 | D39: /m of edge | E39: Placeholder: radius t/2 on every exposed edge (corner-round cutter).
B40: Deburr and polish | C40: 8 | D40: /part | E40: Placeholder: the rounds must be smooth for the corona margin.
B41: Insulating spacers and studs | C41: 3 | D41: /vane | E41: Placeholder: PEEK / POM spacers, studs, per vane.
B42: Labour rate | C42: 45 | D42: /h | E42: Placeholder.
B43: Stack assembly | C43: 0.25 | D43: h per vane or plate | E43: Placeholder: stacking, spacing, alignment.
B44: G10 tube (stator cage) | C44: 60 | D44: /kg | E44: Placeholder: filament-wound tube.
B45: G10 rotor sleeve | C45: 60 | D45: /kg | E45: Placeholder.
...

Sheet BOM fixed
B2: Fixed parts: everything that does not depend on the stack
B4: Total | F4: =SUM(F7:F35) -> 3461 | G4: Excludes contingency (applied on Designs).
B6: group | C6: item | D6: qty | E6: ="unit price ("&CUR&")" -> unit price (EUR) | F6: ="extended ("&CUR&")" -> extended (EUR) | G6: source / note
B7: Magnetic pump | C7: Utron SiFe core, M235-35A, laser-cut + bonded (1.26 kg each) | D7: 6 | E7: 35 | F7: =D7*E7 -> 210 | G7: Quantity: 3 utrons per side; mass from pole_design_variants.json. Placeholder price.
B8: Magnetic pump | C8: Utron winding copper, 1.89 mm², 200 turns (1.07 kg each) | D8: 6 | E8: 18 | F8: =D8*E8 -> 108 | G8: 15 /kg wire + former. Placeholder.
B9: Magnetic pump | C9: Utron NiFe neck strip, cheeks, slot cover, air-break spacer | D9: 6 | E9: 25 | F9: =D9*E9 -> 150 | G9: Placeholder.
B10: Magnetic pump | C10: Utron winding labour (h) | D10: 12 | E10: =LABOUR -> 45 | F10: =D10*E10 -> 540 | G10: 2 h per utron. Placeholder hours.
B11: Magnetic pump | C11: G10 carrier discs | D11: 4 | E11: 25 | F11: =D11*E11 -> 100 | G11: 2 per side. Placeholder.
B12: Magnetic pump | C12: SiFe passive bridges, laminated (counter-rotor) | D12: 12 | E12: 15 | F12: =D12*E12 -> 180 | G12: 6 per side. Placeholder.
B13: Magnetic pump | C13: G10 bridge rings (counter-rotor) | D13: 2 | E13: 60 | F13: =D13*E13 -> 120 | G13: Placeholder.
B14: Magnetic pump | C14: La / Lb gapped EI chokes (1.0 kg iron, 0.41 kg Cu) | D14: 2 | E14: 45 | F14: =D14*E14 -> 90 | G14: First cut, rotor_parts_duty_results.json. Placeholder.
B15: Magnetic pump | C15: D1*-D4* power diodes | D15: 4 | E15: 3 | F15: =D15*E15 -> 12 | G15: Low-voltage, high-current. Placeholder.
B16: Magnetic pump | C16: Node snubbers (RC) | D16: 8 | E16: 1.5 | F16: =D16*E16 -> 12 | G16: Placeholder.
B17: Magnetic pump | C17: Start-kick source (capacitor + push-button) | D17: 1 | E17: 30 | F17: =D17*E17 -> 30 | G17: Open item: 15-20 % of Psi_s, tens of mJ.
B18: AH (hub) | C18: AH coils, 160 turns, on the former | D18: 2 | E18: 15 | F18: =D18*E18 -> 30 | G18: Placeholder.
B19: AH (hub) | C19: AH bypass capacitors, 10 mF / 6.3 V (2 per coil = 20 mF) | D19: 4 | E19: 8 | F19: =D19*E19 -> 32 | G19: The steady cusp (sim/ah-steady-cusp-findings.md). Bipolar parts if the kick polarity is free.
B20: AH (hub) | C20: MnZn rod | D20: 1 | E20: 30 | F20: =D20*E20 -> 30 | G20: Placeholder.
B21: Hub | C21: Bicone electrodes (the cone windings or a slit foil) on their G10 shells | D21: 2 | E21: 40 | F21: =D21*E21 -> 80 | G21: Cone A on the core diode, cone B on the shaft (sim/core-field-findings.md). Placeholder.
B22: Hub | C22: Vacuum sphere (glass vessel) | D22: 1 | E22: 250 | F22: =D22*E22 -> 250 | G22: Placeholder.
... B35: Mechanics | C35: Balancing | D35: 1 | E35: 150 | F35: =D35*E35 -> 150 | G35: Placeholder: rotor and counter-rotor.

Sheet Designs
A1: Designs: the vane matrix with live costs
A2: Columns B-W: results of sim/vane_matrix.py (values, do not edit). Columns X-AL: formulas on Inputs. Al-equivalent masses assume 2700 kg/m³ and are rescaled by the chosen materials' densities.
A4: design | B4: gap (mm) | C4: vane t (mm) | D4: r_out (mm) | E4: sector (deg) | F4: vanes N | G4: V_op (kV) | H4: C_min (pF) | I4: C_max (pF) | J4: kappa | K4: z | L4: P clamped (W) | M4: stacks/side (mm) | N4: tube (mm) | O4: rim onset, handled (kV) | P4: vanes, Al-equiv (kg) | Q4: Ca/Cb, Al-equiv (kg) | R4: vanes (count) | S4: plates (count) | T4: cut (m) | U4: rounded edge (m) | V4: G10 cage (kg) | W4: G10 sleeve (kg) | X4: ="vane metal ("&CUR&")" -> vane metal (EUR) | Y4: ="plate metal ("&CUR&")" -> plate metal (EUR) | Z4: ="cutting ("&CUR&")" -> cutting (EUR) | AA4: ="full rounds ("&CUR&")" -> full rounds (EUR) | AB4: ="deburr + polish ("&CUR&")" -> deburr + polish (EUR) | AC4: ="spacers + assembly ("&CUR&")" -> spacers + assembly (EUR) | AD4: ="G10 cage + sleeve ("&CUR&")" -> G10 cage + sleeve (EUR) | AE4: ="shaft ("&CUR&")" -> shaft (EUR) | AF4: ="HV parts ("&CUR&")" -> HV parts (EUR) | AG4: ="stack subtotal ("&CUR&")" -> stack subtotal (EUR) | AH4: ="fixed BOM ("&CUR&")" -> fixed BOM (EUR) | AI4: ="total incl. contingency ("&CUR&")" -> total incl. contingency (EUR) | AJ4: ="per watt ("&CUR&")" -> per watt (EUR) | AK4: meets targets | AL4: score
A5: 1 | B5: 3 | C5: 1.5 | D5: 150 | E5: 18 | F5: 4 | G5: 7.264419 | H5: 15.332566 | I5: 409.94498 | J5: 26.73688 | K5: 1.487413 | L5: 0.895443 | M5: 51 | N5: 694 | O5: 8.205731 | P5: 1.814237 | Q5: 2.035752 | R5: 16 | S5: 8 | T5: 48.479644 | U5: 39.306193 | V5: 1.540305 | W5: 0.309939 | X5: =P5*RHO_VANE/2700*(1+SCRAP)*PRICE_VANE -> 21.716417 | Y5: =Q5*RHO_PLATE/2700*(1+SCRAP)*PRICE_PLATE -> 24.367951 | Z5: =T5*CUT_M+(R5+S5)*CUT_SET -> 96.719466 | AA5: =U5*ROUND_M -> 196.53097 | AB5: =(R5+S5)*FINISH_PART -> 192 | AC5: =R5*SPACER_VANE+(R5+S5)*ASM_H*LABOUR -> 318 | AD5: =V5*G10_CAGE+W5*G10_SLEEVE -> 111.01464 | AE5: =N5/1000*SHAFT_M+SHAFT_SET -> 163.28 | AF5: =2*ROUNDUP(G5*1000/V_ZENER,0)*PRICE_Z+5*ROUNDUP(G5*DIODE_SAFETY/V_STICK,0)*PRICE_STICK -> 56.9 | AG5: =SUM(X5:AF5) -> 1180.5294 | AH5: =FIXED_BOM -> 3461 | AI5: =(AG5+AH5)*(1+CONT) -> 5337.7589 | AJ5: =IF(L5>0,AI5/L5,1000000000000) -> 5961.0258 | AK5: =IF(AND(G5>=V_NEED,L5>=P_MIN,K5>=Z_MIN,F5<=N_CAP,D5<=R_MAX,OR(CORONA_REQ=0,O5>=G5)),1,0) -> 0 | AL5: =IF(AK5=1,IF(OBJECTIVE=1,AI5,AJ5),1000000000000)+ROW()*0.000000001 -> 1000000000000
A6: 2 | B6: 3 | C6: 1.5 | D6: 150 | E6: 18 | F6: 6 | G6: 7.264419 | H6: 22.951175 | I6: 644.19925 | J6: 28.068247 | K6: 1.542933 | L6: 1.517259 | M6: 73.5 | N6: 739 | O6: 8.205731 | P6: 2.721355 | Q6: 2.54469 | R6: 24 | S6: 10 | T6: 70.206191 | U6: 56.446015 | V6: 1.883443 | W6: 0.378985 | X6: =P6*RHO_VANE/2700*(1+SCRAP)*PRICE_VANE -> 32.574619 | Y6: =Q6*RHO_PLATE/2700*(1+SCRAP)*PRICE_PLATE -> 30.459939 | Z6: =T6*CUT_M+(R6+S6)*CUT_SET -> 139.30929 | AA6: =U6*ROUND_M -> 282.23007 | AB6: =(R6+S6)*FINISH_PART -> 272 | AC6: =R6*SPACER_VANE+(R6+S6)*ASM_H*LABOUR -> 454.5 | AD6: =V6*G10_CAGE+W6*G10_SLEEVE -> 135.74568 | AE6: =N6/1000*SHAFT_M+SHAFT_SET -> 168.68 | AF6: =2*ROUNDUP(G6*1000/V_ZENER,0)*PRICE_Z+5*ROUNDUP(G6*DIODE_SAFETY/V_STICK,0)*PRICE_STICK -> 56.9 | AG6: =SUM(X6:AF6) -> 1572.3996 | AH6: =FIXED_BOM -> 3461 | AI6: =(AG6+AH6)*(1+CONT) -> 5788.4095 | AJ6: =IF(L6>0,AI6/L6,1000000000000) -> 3815.0438 | AK6: =IF(AND(G6>=V_NEED,L6>=P_MIN,K6>=Z_MIN,F6<=N_CAP,D6<=R_MAX,OR(CORONA_REQ=0,O6>=G6)),1,0) -> 0 | AL6: =IF(AK6=1,IF(OBJECTIVE=1,AI6,AJ6),1000000000000)+ROW()*0.000000001 -> 1000000000000
A7: 3 | B7: 3 | C7: 1.5 | D7: 150 | E7: 18 | F7: 8 | G7: 7.264419 | H7: 30.569785 | I7: 878.45353 | J7: 28.736007 | K7: 1.571407 | L7: 2.142792 | M7: 100.5 | N7: 793 | O7: 8.205731 | P7: 3.628474 | Q7: 3.562566 | R7: 32 | S7: 14 | T7: 94.446013 | U7: 76.099112 | V7: 2.295207 | W7: 0.461841 | X7: =P7*RHO_VANE/2700*(1+SCRAP)*PRICE_VANE -> 43.432834 | Y7: =Q7*RHO_PLATE/2700*(1+SCRAP)*PRICE_PLATE -> 42.643915 | Z7: =T7*CUT_M+(R7+S7)*CUT_SET -> 187.66902 | AA7: =U7*ROUND_M -> 380.49556 | AB7: =(R7+S7)*FINISH_PART -> 368 | AC7: =R7*SPACER_VANE+(R7+S7)*ASM_H*LABOUR -> 613.5 | AD7: =V7*G10_CAGE+W7*G10_SLEEVE -> 165.42288 | AE7: =N7/1000*SHAFT_M+SHAFT_SET -> 175.16 | AF7: =2*ROUNDUP(G7*1000/V_ZENER,0)*PRICE_Z+5*ROUNDUP(G7*DIODE_SAFETY/V_STICK,0)*PRICE_STICK -> 56.9 | AG7: =SUM(X7:AF7) -> 2033.2242 | AH7: =FIXED_BOM -> 3461 | AI7: =(AG7+AH7)*(1+CONT) -> 6318.3578 | AJ7: =IF(L7>0,AI7/L7,1000000000000) -> 2948.6566 | AK7: =IF(AND(G7>=V_NEED,L7>=P_MIN,K7>=Z_MIN,F7<=N_CAP,D7<=R_MAX,OR(CORONA_REQ=0,O7>=G7)),1,0) -> 0 | AL7: =IF(AK7=1,IF(OBJECTIVE=1,AI7,AJ7),1000000000000)+ROW()*0.000000001 -> 1000000000000
A8: 4 | B8: 3 | C8: 1.5 | D8: 150 | E8: 18 | F8: 10 | G8: 7.264419 | H8: 38.188394 | I8: 1112.7078 | J8: 29.137329 | K8: 1.588674 | L8: 2.768277 | M8: 123 | N8: 838 | O8: 8.205731 | P8: 4.535592 | Q8: 4.071504 | R8: 40 | S8: 16 | T8: 116.17256 | U8: 93.238934 | V8: 2.638345 | W8: 0.530886 | X8: =P8*RHO_VANE/2700*(1+SCRAP)*PRICE_VANE -> 54.291036 | Y8: =Q8*RHO_PLATE/2700*(1+SCRAP)*PRICE_PLATE -> 48.735903 | Z8: =T8*CUT_M+(R8+S8)*CUT_SET -> 230.25884 | AA8: =U8*ROUND_M -> 466.19467 | AB8: =(R8+S8)*FINISH_PART -> 448 | AC8: =R8*SPACER_VANE+(R8+S8)*ASM_H*LABOUR -> 750 | AD8: =V8*G10_CAGE+W8*G10_SLEEVE -> 190.15386 | AE8: =N8/1000*SHAFT_M+SHAFT_SET -> 180.56 | AF8: =2*ROUNDUP(G8*1000/V_ZENER,0)*PRICE_Z+5*ROUNDUP(G8*DIODE_SAFETY/V_STICK,0)*PRICE_STICK -> 56.9 | AG8: =SUM(X8:AF8) -> 2425.0943 | AH8: =FIXED_BOM -> 3461 | AI8: =(AG8+AH8)*(1+CONT) -> 6769.0085 | AJ8: =IF(L8>0,AI8/L8,1000000000000) -> 2445.2063 | AK8: =IF(AND(G8>=V_NEED,L8>=P_MIN,K8>=Z_MIN,F8<=N_CAP,D8<=R_MAX,OR(CORONA_REQ=0,O8>=G8)),1,0) -> 0 | AL8: =IF(AK8=1,IF(OBJECTIVE=1,AI8,AJ8),1000000000000)+ROW()*0.000000001 -> 1000000000000
A9: 5 | B9: 3 | C9: 1.5 | D9: 150 | E9: 18 | F9: 12 | G9: 7.264419 | H9: 45.807003 | I9: 1346.9621 | J9: 29.405156 | K9: 1.599931 | L9: 3.395716 | M9: 145.5 | N9: 883 | O9: 8.205731 | P9: 5.44271 | Q9: 4.580442 | R9: 48 | S9: 18 | T9: 137.89911 | U9: 110.37876 | V9: 2.981482 | W9: 0.599932 | X9: =P9*RHO_VANE/2700*(1+SCRAP)*PRICE_VANE -> 65.149239 | Y9: =Q9*RHO_PLATE/2700*(1+SCRAP)*PRICE_PLATE -> 54.827891 | Z9: =T9*CUT_M+(R9+S9)*CUT_SET -> 272.84866 | AA9: =U9*ROUND_M -> 551.89378 | AB9: =(R9+S9)*FINISH_PART -> 528 | AC9: =R9*SPACER_VANE+(R9+S9)*ASM_H*LABOUR -> 886.5 | AD9: =V9*G10_CAGE+W9*G10_SLEEVE -> 214.88484 | AE9: =N9/1000*SHAFT_M+SHAFT_SET -> 185.96 | AF9: =2*ROUNDUP(G9*1000/V_ZENER,0)*PRICE_Z+5*ROUNDUP(G9*DIODE_SAFETY/V_STICK,0)*PRICE_STICK -> 56.9 | AG9: =SUM(X9:AF9) -> 2816.9644 | AH9: =FIXED_BOM -> 3461 | AI9: =(AG9+AH9)*(1+CONT) -> 7219.6591 | AJ9: =IF(L9>0,AI9/L9,1000000000000) -> 2126.108 | AK9: =IF(AND(G9>=V_NEED,L9>=P_MIN,K9>=Z_MIN,F9<=N_CAP,D9<=R_MAX,OR(CORONA_REQ=0,O9>=G9)),1,0) -> 0 | AL9: =IF(AK9=1,IF(OBJECTIVE=1,AI9,AJ9),1000000000000)+ROW()*0.000000001 -> 1000000000000
A10: 6 | B10: 3 | C10: 1.5 | D10: 150 | E10: 18 | F10: 16 | G10: 7.264419 | H10: 61.044221 | I10: 1815.4706 | J10: 29.740254 | K10: 1.614212 | L10: 4.64956 | M10: 195 | N10: 982 | O10: 8.205731 | P10: 7.256947 | Q10: 6.107256 | R10: 64 | S10: 24 | T10: 183.86548 | U10: 147.17167 | V10: 3.736384 | W10: 0.751833 | X10: =P10*RHO_VANE/2700*(1+SCRAP)*PRICE_VANE -> 86.865656 | Y10: =Q10*RHO_PLATE/2700*(1+SCRAP)*PRICE_PLATE -> 73.103854 | Z10: =T10*CUT_M+(R10+S10)*CUT_SET -> 363.79822 | AA10: =U10*ROUND_M -> 735.85838 | AB10: =(R10+S10)*FINISH_PART -> 704 | AC10: =R10*SPACER_VANE+(R10+S10)*ASM_H*LABOUR -> 1182 | AD10: =V10*G10_CAGE+W10*G10_SLEEVE -> 269.29302 | AE10: =N10/1000*SHAFT_M+SHAFT_SET -> 197.84 | AF10: =2*ROUNDUP(G10*1000/V_ZENER,0)*PRICE_Z+5*ROUNDUP(G10*DIODE_SAFETY/V_STICK,0)*PRICE_STICK -> 56.9 | AG10: =SUM(X10:AF10) -> 3669.6591 | AH10: =FIXED_BOM -> 3461 | AI10: =(AG10+AH10)*(1+CONT) -> 8200.258 | AJ10: =IF(L10>0,AI10/L10,1000000000000) -> 1763.6632 | AK10: =IF(AND(G10>=V_NEED,L10>=P_MIN,K10>=Z_MIN,F10<=N_CAP,D10<=R_MAX,OR(CORONA_REQ=0,O10>=G10)),1,0) -> 0 | AL10: =IF(AK10=1,IF(OBJECTIVE=1,AI10,AJ10),1000000000000)+ROW()*0.000000001 -> 1000000000000
A11: 7 | B11: 3 | C11: 1.5 | D11: 150 | E11: 22 | F11: 4 | G11: 7.264419 | H11: 20.693572 | I11: 496.3554 | J11: 23.98597 | K11: 1.501887 | L11: 1.107758 | M11: 51 | N11: 694 | O11: 8.205731 | P11: 2.08567 | Q11: 2.035752 | R11: 16 | S11: 8 | T11: 48.479644 | U11: 39.306193 | V11: 1.540305 | W11: 0.309939 | X11: =P11*RHO_VANE/2700*(1+SCRAP)*PRICE_VANE -> 24.96547 | Y11: =Q11*RHO_PLATE/2700*(1+SCRAP)*PRICE_PLATE -> 24.367951 | Z11: =T11*CUT_M+(R11+S11)*CUT_SET -> 96.719466 | AA11: =U11*ROUND_M -> 196.53097 | AB11: =(R11+S11)*FINISH_PART -> 192 | AC11: =R11*SPACER_VANE+(R11+S11)*ASM_H*LABOUR -> 318 | AD11: =V11*G10_CAGE+W11*G10_SLEEVE -> 111.01464 | AE11: =N11/1000*SHAFT_M+SHAFT_SET -> 163.28 | AF11: =2*ROUNDUP(G11*1000/V_ZENER,0)*PRICE_Z+5*ROUNDUP(G11*DIODE_SAFETY/V_STICK,0)*PRICE_STICK -> 56.9 | AG11: =SUM(X11:AF11) -> 1183.7785 | AH11: =FIXED_BOM -> 3461 | AI11: =(AG11+AH11)*(1+CONT) -> 5341.4953 | AJ11: =IF(L11>0,AI11/L11,1000000000000) -> 4821.8973 | AK11: =IF(AND(G11>=V_NEED,L11>=P_MIN,K11>=Z_MIN,F11<=N_CAP,D11<=R_MAX,OR(CORONA_REQ=0,O11>=G11)),1,0) -> 0 | AL11: =IF(AK11=1,IF(OBJECTIVE=1,AI11,AJ11),1000000000000)+ROW()*0.000000001 -> 1000000000000
A12: 8 | B12: 3 | C12: 1.5 | D12: 150 | E12: 22 | F12: 6 | G12: 7.264419 | H12: 31.375614 | I12: 779.98706 | J12: 24.859659 | K12: 1.548578 | L12: 1.851634 | M12: 78 | N12: 748 | O12: 8.205731 | P12: 3.128506 | Q12: 3.053628 | R12: 24 | S12: 12 | T12: 72.719465 | U12: 58.959289 | V12: 1.95207 | W12: 0.392795 | X12: =P12*RHO_VANE/2700*(1+SCRAP)*PRICE_VANE -> 37.448217 | Y12: =Q12*RHO_PLATE/2700*(1+SCRAP)*PRICE_PLATE -> 36.551927 | Z12: =T12*CUT_M+(R12+S12)*CUT_SET -> 145.0792 | AA12: =U12*ROUND_M -> 294.79645 | AB12: =(R12+S12)*FINISH_PART -> 288 | AC12: =R12*SPACER_VANE+(R12+S12)*ASM_H*LABOUR -> 477 | AD12: =V12*G10_CAGE+W12*G10_SLEEVE -> 140.6919 | AE12: =N12/1000*SHAFT_M+SHAFT_SET -> 169.76 | AF12: =2*ROUNDUP(G12*1000/V_ZENER,0)*PRICE_Z+5*ROUNDUP(G12*DIODE_SAFETY/V_STICK,0)*PRICE_STICK -> 56.9 | AG12: =SUM(X12:AF12) -> 1646.2277 | AH12: =FIXED_BOM -> 3461 | AI12: =(AG12+AH12)*(1+CONT) -> 5873.3118 | AJ12: =IF(L12>0,AI12/L12,1000000000000) -> 3171.9615 | AK12: =IF(AND(G12>=V_NEED,L12>=P_MIN,K12>=Z_MIN,F12<=N_CAP,D12<=R_MAX,OR(CORONA_REQ=0,O12>=G12)),1,0) -> 0 | AL12: =IF(AK12=1,IF(OBJECTIVE=1,AI12,AJ12),1000000000000)+ROW()*0.000000001 -> 1000000000000
A13: 9 | B13: 3 | C13: 1.5 | D13: 150 | E13: 22 | F13: 8 | G13: 7.264419 | H13: 42.057655 | I13: 1063.6187 | J13: 25.289539 | K13: 1.572295 | L13: 2.599078 | M13: 105 | N13: 802 | O13: 8.205731 | P13: 4.171341 | Q13: 4.071504 | R13: 32 | S13: 16 | T13: 96.959287 | U13: 78.612386 | V13: 2.363835 | W13: 0.47565 | X13: =P13*RHO_VANE/2700*(1+SCRAP)*PRICE_VANE -> 49.930952 | Y13: =Q13*RHO_PLATE/2700*(1+SCRAP)*PRICE_PLATE -> 48.735903 | Z13: =T13*CUT_M+(R13+S13)*CUT_SET -> 193.43893 | AA13: =U13*ROUND_M -> 393.06193 | AB13: =(R13+S13)*FINISH_PART -> 384 | AC13: =R13*SPACER_VANE+(R13+S13)*ASM_H*LABOUR -> 636 | AD13: =V13*G10_CAGE+W13*G10_SLEEVE -> 170.3691 | AE13: =N13/1000*SHAFT_M+SHAFT_SET -> 176.24 | AF13: =2*ROUNDUP(G13*1000/V_ZENER,0)*PRICE_Z+5*ROUNDUP(G13*DIODE_SAFETY/V_STICK,0)*PRICE_STICK -> 56.9 | AG13: =SUM(X13:AF13) -> 2108.6768 | AH13: =FIXED_BOM -> 3461 | AI13: =(AG13+AH13)*(1+CONT) -> 6405.1283 | AJ13: =IF(L13>0,AI13/L13,1000000000000) -> 2464.3848 | AK13: =IF(AND(G13>=V_NEED,L13>=P_MIN,K13>=Z_MIN,F13<=N_CAP,D13<=R_MAX,OR(CORONA_REQ=0,O13>=G13)),1,0) -> 0 | AL13: =IF(AK13=1,IF(OBJECTIVE=1,AI13,AJ13),1000000000000)+ROW()*0.000000001 -> 1000000000000
A14: 10 | B14: 3 | C14: 1.5 | D14: 150 | E14: 22 | F14: 10 | G14: 7.264419 | H14: 52.739697 | I14: 1347.2504 | J14: 25.545281 | K14: 1.586429 | L14: 3.347026 | M14: 127.5 | N14: 847 | O14: 8.205731 | P14: 5.214176 | Q14: 4.580442 | R14: 40 | S14: 18 | T14: 118.68583 | U14: 95.752208 | V14: 2.706972 | W14: 0.544696 | X14: =P14*RHO_VANE/2700*(1+SCRAP)*PRICE_VANE -> 62.413687 | Y14: =Q14*RHO_PLATE/2700*(1+SCRAP)*PRICE_PLATE -> 54.827891 | Z14: =T14*CUT_M+(R14+S14)*CUT_SET -> 236.02875 | AA14: =U14*ROUND_M -> 478.76104 | AB14: =(R14+S14)*FINISH_PART -> 464 | AC14: =R14*SPACER_VANE+(R14+S14)*ASM_H*LABOUR -> 772.5 | AD14: =V14*G10_CAGE+W14*G10_SLEEVE -> 195.10008 | AE14: =N14/1000*SHAFT_M+SHAFT_SET -> 181.64 | AF14: =2*ROUNDUP(G14*1000/V_ZENER,0)*PRICE_Z+5*ROUNDUP(G14*DIODE_SAFETY/V_STICK,0)*PRICE_STICK -> 56.9 | AG14: =SUM(X14:AF14) -> 2502.1714 | AH14: =FIXED_BOM -> 3461 | AI14: =(AG14+AH14)*(1+CONT) -> 6857.6472 | AJ14: =IF(L14>0,AI14/L14,1000000000000) -> 2048.8778 | AK14: =IF(AND(G14>=V_NEED,L14>=P_MIN,K14>=Z_MIN,F14<=N_CAP,D14<=R_MAX,OR(CORONA_REQ=0,O14>=G14)),1,0) -> 0 | AL14: =IF(AK14=1,IF(OBJECTIVE=1,AI14,AJ14),1000000000000)+ROW()*0.000000001 -> 1000000000000
A15: 11 | B15: 3 | C15: 1.5 | D15: 150 | E15: 22 | F15: 12 | G15: 7.264419 | H15: 63.421738 | I15: 1630.882 | J15: 25.714875 | K15: 1.59581 | L15: 4.095217 | M15: 154.5 | N15: 901 | O15: 8.205731 | P15: 6.257011 | Q15: 5.598318 | R15: 48 | S15: 22 | T15: 142.92566 | U15: 115.4053 | V15: 3.118737 | W15: 0.627551 | X15: =P15*RHO_VANE/2700*(1+SCRAP)*PRICE_VANE -> 74.896422 | Y15: =Q15*RHO_PLATE/2700*(1+SCRAP)*PRICE_PLATE -> 67.011866 | Z15: =T15*CUT_M+(R15+S15)*CUT_SET -> 284.38848 | AA15: =U15*ROUND_M -> 577.02652 | AB15: =(R15+S15)*FINISH_PART -> 560 | AC15: =R15*SPACER_VANE+(R15+S15)*ASM_H*LABOUR -> 931.5 | AD15: =V15*G10_CAGE+W15*G10_SLEEVE -> 224.77728 | AE15: =N15/1000*SHAFT_M+SHAFT_SET -> 188.12 | AF15: =2*ROUNDUP(G15*1000/V_ZENER,0)*PRICE_Z+5*ROUNDUP(G15*DIODE_SAFETY/V_STICK,0)*PRICE_STICK -> 56.9 | AG15: =SUM(X15:AF15) -> 2964.6206 | AH15: =FIXED_BOM -> 3461 | AI15: =(AG15+AH15)*(1+CONT) -> 7389.4637 | AJ15: =IF(L15>0,AI15/L15,1000000000000) -> 1804.4132 | AK15: =IF(AND(G15>=V_NEED,L15>=P_MIN,K15>=Z_MIN,F15<=N_CAP,D15<=R_MAX,OR(CORONA_REQ=0,O15>=G15)),1,0) -> 0 | AL15: =IF(AK15=1,IF(OBJECTIVE=1,AI15,AJ15),1000000000000)+ROW()*0.000000001 -> 1000000000000
A16: 12 | B16: 3 | C16: 1.5 | D16: 150 | E16: 22 | F16: 16 | G16: 7.264419 | H16: 84.785821 | I16: 2198.1454 | J16: 25.92586 | K16: 1.606658 | L16: 5.586156 | M16: 208.5 | N16: 1009 | O16: 8.205731 | P16: 8.342682 | Q16: 7.63407 | R16: 64 | S16: 30 | T16: 191.4053 | U16: 154.7115 | V16: 3.942266 | W16: 0.793261 | X16: =P16*RHO_VANE/2700*(1+SCRAP)*PRICE_VANE -> 99.861904 | Y16: =Q16*RHO_PLATE/2700*(1+SCRAP)*PRICE_PLATE -> 91.379818 | Z16: =T16*CUT_M+(R16+S16)*CUT_SET -> 381.10795 | AA16: =U16*ROUND_M -> 773.55749 | AB16: =(R16+S16)*FINISH_PART -> 752 | AC16: =R16*SPACER_VANE+(R16+S16)*ASM_H*LABOUR -> 1249.5 | AD16: =V16*G10_CAGE+W16*G10_SLEEVE -> 284.13162 | AE16: =N16/1000*SHAFT_M+SHAFT_SET -> 201.08 | AF16: =2*ROUNDUP(G16*1000/V_ZENER,0)*PRICE_Z+5*ROUNDUP(G16*DIODE_SAFETY/V_STICK,0)*PRICE_STICK -> 56.9 | AG16: =SUM(X16:AF16) -> 3889.5188 | AH16: =FIXED_BOM -> 3461 | AI16: =(AG16+AH16)*(1+CONT) -> 8453.0966 | AJ16: =IF(L16>0,AI16/L16,1000000000000) -> 1513.2224 | AK16: =IF(AND(G16>=V_NEED,L16>=P_MIN,K16>=Z_MIN,F16<=N_CAP,D16<=R_MAX,OR(CORONA_REQ=0,O16>=G16)),1,0) -> 0 | AL16: =IF(AK16=1,IF(OBJECTIVE=1,AI16,AJ16),1000000000000)+ROW()*0.000000001 -> 1000000000000
... A2704: 2700 | B2704: 10 | C2704: 4 | D2704: 300 | E2704: 26 | F2704: 16 | G2704: 20.62 | H2704: 544.82338 | I2704: 3525.9051 | J2704: 6.471648 | K2704: 1.363029 | L2704: 51.137353 | M2704: 676 | N2704: 1972 | O2704: 19.540911 | P2704: 92.56655 | Q2704: 100.93937 | R2704: 64 | S2704: 34 | T2704: 403.99467 | U2704: 337.14158 | V2704: 21.198633 | W2704: 2.227882 | X2704: =P2704*RHO_VANE/2700*(1+SCRAP)*PRICE_VANE -> 1108.0216 | Y2704: =Q2704*RHO_PLATE/2700*(1+SCRAP)*PRICE_PLATE -> 1208.2443 | Z2704: =T2704*CUT_M+(R2704+S2704)*CUT_SET -> 703.99201 | AA2704: =U2704*ROUND_M -> 1685.7079 | AB2704: =(R2704+S2704)*FINISH_PART -> 784 | AC2704: =R2704*SPACER_VANE+(R2704+S2704)*ASM_H*LABOUR -> 1294.5 | AD2704: =V2704*G10_CAGE+W2704*G10_SLEEVE -> 1405.5909 | AE2704: =N2704/1000*SHAFT_M+SHAFT_SET -> 316.64 | AF2704: =2*ROUNDUP(G2704*1000/V_ZENER,0)*PRICE_Z+5*ROUNDUP(G2704*DIODE_SAFETY/V_STICK,0)*PRICE_STICK -> 149.8 | AG2704: =SUM(X2704:AF2704) -> 8656.4967 | AH2704: =FIXED_BOM -> 3461 | AI2704: =(AG2704+AH2704)*(1+CONT) -> 13935.121 | AJ2704: =IF(L2704>0,AI2704/L2704,1000000000000) -> 272.50376 | AK2704: =IF(AND(G2704>=V_NEED,L2704>=P_MIN,K2704>=Z_MIN,F2704<=N_CAP,D2704<=R_MAX,OR(CORONA_REQ=0,O2704>=G2704)),1,0) -> 0 | AL2704: =IF(AK2704=1,IF(OBJECTIVE=1,AI2704,AJ2704),1000000000000)+ROW()*0.000000001 -> 1000000000000

Sheet Notes
B2: Geometry-derived quantities on Designs (values computed by docs/make_cost_sheet.py)
B3: Vanes: 6 sectors on a 60 deg pitch, stator = rotor width w, from r_in 50 mm to r_out. Stator vane: sectors on an outer ring r_out..r_out+12 (held in the cage). Rotor vane: an inner ring 20.5..50 (on the sleeve) with the sectors.
B4: Rounded edges (full round R = t/2): the stator's sides, inner arcs and the ring's inner edge between sectors; the rotor's sides, outer arcs and the ring's outer edge; both rims of each Ca / Cb plate.
B5: Cut length: the rounded edges plus the stator's outer circle (r_out+12) and the rotor's bore (20.5); both circles of each plate. Counts: 4N vanes and 2 (n_ca+1) plates for the two sides.
B6: G10: the stator cage r_out+12..r_out+16 and the rotor sleeve 12.5..20.5, each over the stacks plus 50 mm per side for the bearing spiders' seats, at 1850 kg/m³.
B7: Masses: the matrix's rotor and stator vanes (sectors and rings) and full-annulus plates at 2700 kg/m³; the rounds take < 1 % off and are ignored.
B9: What is not in the cost
B10: Re-sizing the AH or the magnetic pump for more than the delivered steady ampere-turns; the shaft and bearings for the heavier rotors at large radius (not checked); design, test equipment, the vacuum system, tooling.
B11: The electric field on the core: the electrostatic circuit's HV side is on the rotor (sim/core_field.py, sim/core-field-findings.md). The core diode Dk charges cone A to the node's peak, about the operating peak, and C_core holds it; cone B sits on the shaft. A design qualifies when its operating peak reaches E x spacing.
B12: The pump's power is unchanged by the core. Its leakage must stay above about 1 GOhm (0.17 W at 13 kV); below about 0.06 GOhm the pump does not start. HV parts on Designs count 5 diode stacks: D1-D4 and Dk.
